Workbook

Sheet Assumptions
A1: BUZBO — Budget Assumptions | Bridge Jun–Dec 2026
A2: Blue = inputs you can change | All amounts in EUR | Salaries = net amounts
A4: PEOPLE — Net salaries (employer cost = net × 1.42 gross-up)
A5: Gross-up factor (net → employer total cost) | B5: 1.42 | C5: NL: income tax + employee NI + employer NI ≈ +42% on net
A6: CEO — Anouk (net/month) | B6: 3500 | C6: Employer cost ≈ €4,260/mo
A7: CCO — Shinead (net/month) | B7: 3500 | C7: Employer cost ≈ €4,260/mo
A8: CTO — Tommy (net/month) | B8: 3000 | C8: Employer cost ≈ €4,260/mo. Starts July.
A9: Marketing PT × 2 (net/month each, 3d/wk) | B9: 2100 | C9: FT net €3,500 × 3/5 = €2,100 net. Starts July.
A10: Marketing PT headcount | B10: 2
A11: Marketing Content Creator FT (net/month) — VACANCY | B11: 3300 | C11: Full-time. Starts July. Employer cost ≈ €4,970/mo
A12: Designer — Freelancer (invoice/month) | B12: 4000 | C12: Day rate freelancer. No employer costs. Starts July.
A13: UX/UI — Chinar PT (net/month) | B13: 1500 | C13: Min wage NL 2026: €2,560 gross FT × 60% = €1,536 gross → ~€1,100 net. Must stay ≥ min wage.
A15: PEOPLE — Flexible Shell
A16: Event host per city (per event) | B16: 300 | C16: Freelance fee per event per city
A17: Event support crew (per event) | B17: 150 | C17: 2 support crew × €75 each
A18: Content creators — students/side jobs (monthly) | B18: 1500 | C18: 3 creators × €500/month
A20: EVENTS
A21: Cities active | B21: 3 | C21: Den Haag, Amsterdam, Rotterdam
A22: Events per month | B22: 3 | C22: 1 per city per month
A23: Food & drinks per event | B23: 500
A24: Event promotion per event | B24: 200 | C24: Paid social, print, etc.
A25: Venue / location per event | B25: 0 | C25: Update when paid venues needed
A27: MARKETING & OPERATIONS
A28: Marketing budget (monthly) | B28: 5000 | C28: Paid channels, campaigns, tools
A29: Office / coworking (monthly) | B29: 1000 | C29: Mauritskade / Titaan
A30: Software per person per month | B30: 100 | C30: Notion, Slack, Canva, design tools
A31: Headcount (for software calc) | B31: 10 | C31: All contracted team members + vacancy slot
A32: App hosting & infra (monthly) | B32: 300 | C32: Scales with users; review at 1k+ MAU
A33: Domestic travel NL (monthly) | B33: 400 | C33: Train, intercity events across NL
A35: LEGAL, FINANCE & ADMIN
A36: Legal — incorporation + agreements (one-off) | B36: 3500 | C36: Delaware / NL BV, Shinead new agreement, investor docs
A37: Legal — ongoing (monthly) | B37: 200 | C37: Ad hoc advice, contract updates
A38: Accountancy / bookkeeping (monthly) | B38: 500 | C38: Monthly close + VAT returns
A39: Insurance — liability + D&O (monthly) | B39: 300 | C39: Beroepsaansprakelijkheid + directors
A41: PEOPLE — Benefits & Culture
A42: Team outing (per quarter) | B42: 500 | C42: Quarterly team experience
A43: Benefits allowance (monthly, all staff) | B43: 200 | C43: Mobility / wellness
A45: CONTINGENCY
A46: Contingency buffer (%) | B46: 0.12 | C46: 12% on total costs — standard pre-revenue
A48: REVENUE ASSUMPTIONS
...

Sheet Monthly P&L
A1: BUZBO — Monthly P&L | Bridge Jun–Dec 2026 | Salaries start July
B4: Jun-26 | C4: Jul-26 | D4: Aug-26 | E4: Sep-26 | F4: Oct-26 | G4: Nov-26 | H4: Dec-26 | I4: TOTAL
A5: REVENUE
A6: Event ticket revenue | B6: 217 | C6: 200 | D6: 400 | E6: 600 | F6: 800 | G6: 1000 | H6: 1000 | I6: =SUM(B6:H6) -> 4217
A7: Membership revenue (recurring) | B7: 0 | C7: 500 | D7: 1000 | E7: 5000 | F7: 10000 | G7: 25000 | H7: 50000 | I7: =SUM(B7:H7) -> 91500
A8: B2B talent introduction revenue | B8: 0 | C8: 0 | D8: =Assumptions!B47 -> 0 | E8: =Assumptions!B47 -> 0 | F8: =Assumptions!B47*1.5 -> 0 | G8: =Assumptions!B47*2 -> 0 | H8: =Assumptions!B47*2 -> 0 | I8: =SUM(B8:H8) -> 0
A9: TOTAL REVENUE | B9: =B6+B7+B8 -> 217 | C9: =C6+C7+C8 -> 700 | D9: =D6+D7+D8 -> 1400 | E9: =E6+E7+E8 -> 5600 | F9: =F6+F7+F8 -> 10800 | G9: =G6+G7+G8 -> 26000 | H9: =H6+H7+H8 -> 51000 | I9: =SUM(B9:H9) -> 95717
A11: COSTS — PEOPLE (employer total cost = net × 1.42)
A12: CEO — Anouk | B12: - | C12: =Assumptions!B6*Assumptions!B5 -> 4970 | D12: =Assumptions!B6*Assumptions!B5 -> 4970 | E12: =Assumptions!B6*Assumptions!B5 -> 4970 | F12: =Assumptions!B6*Assumptions!B5 -> 4970 | G12: =Assumptions!B6*Assumptions!B5 -> 4970 | H12: =Assumptions!B6*Assumptions!B5 -> 4970 | I12: =SUM(B12:H12) -> 29820
A13: CCO — Shinead | B13: 0 | C13: =Assumptions!B7*Assumptions!B5 -> 4970 | D13: =Assumptions!B7*Assumptions!B5 -> 4970 | E13: =Assumptions!B7*Assumptions!B5 -> 4970 | F13: =Assumptions!B7*Assumptions!B5 -> 4970 | G13: =Assumptions!B7*Assumptions!B5 -> 4970 | H13: =Assumptions!B7*Assumptions!B5 -> 4970 | I13: =SUM(B13:H13) -> 29820
A14: CTO — Tommy | B14: 0 | C14: =Assumptions!B8*Assumptions!B5 -> 4260 | D14: =Assumptions!B8*Assumptions!B5 -> 4260 | E14: =Assumptions!B8*Assumptions!B5 -> 4260 | F14: =Assumptions!B8*Assumptions!B5 -> 4260 | G14: =Assumptions!B8*Assumptions!B5 -> 4260 | H14: =Assumptions!B8*Assumptions!B5 -> 4260 | I14: =SUM(B14:H14) -> 25560
A15: Marketing PT × 2 (employer cost) | B15: 0 | C15: =Assumptions!B9*Assumptions!B5*Assumptions!B10 -> 5964 | D15: =Assumptions!B9*Assumptions!B5*Assumptions!B10 -> 5964 | E15: =Assumptions!B9*Assumptions!B5*Assumptions!B10 -> 5964 | F15: =Assumptions!B9*Assumptions!B5*Assumptions!B10 -> 5964 | G15: =Assumptions!B9*Assumptions!B5*Assumptions!B10 -> 5964 | H15: =Assumptions!B9*Assumptions!B5*Assumptions!B10 -> 5964 | I15: =SUM(B15:H15) -> 35784
A16: Marketing Content Creator FT (employer cost) — vacancy | B16: 0 | C16: =Assumptions!B11*Assumptions!B5 -> 4686 | D16: =Assumptions!B11*Assumptions!B5 -> 4686 | E16: =Assumptions!B11*Assumptions!B5 -> 4686 | F16: =Assumptions!B11*Assumptions!B5 -> 4686 | G16: =Assumptions!B11*Assumptions!B5 -> 4686 | H16: =Assumptions!B11*Assumptions!B5 -> 4686 | I16: =SUM(B16:H16) -> 28116
A17: Designer — Freelancer (invoice, no employer cost) | B17: 0 | C17: =Assumptions!B12 -> 4000 | D17: =Assumptions!B12 -> 4000 | E17: =Assumptions!B12 -> 4000 | F17: =Assumptions!B12 -> 4000 | G17: =Assumptions!B12 -> 4000 | H17: =Assumptions!B12 -> 4000 | I17: =SUM(B17:H17) -> 24000
A18: UX/UI — Chinar PT (employer cost) | B18: 0 | C18: =Assumptions!B13*Assumptions!B5 -> 2130 | D18: =Assumptions!B13*Assumptions!B5 -> 2130 | E18: =Assumptions!B13*Assumptions!B5 -> 2130 | F18: =Assumptions!B13*Assumptions!B5 -> 2130 | G18: =Assumptions!B13*Assumptions!B5 -> 2130 | H18: =Assumptions!B13*Assumptions!B5 -> 2130 | I18: =SUM(B18:H18) -> 12780
A19: Event hosts + support crew (per event × 3) | B19: =(Assumptions!B15+Assumptions!B16)*Assumptions!B20 -> 0 | C19: =(Assumptions!B15+Assumptions!B16)*Assumptions!B20 -> 0 | D19: =(Assumptions!B15+Assumptions!B16)*Assumptions!B20 -> 0 | E19: =(Assumptions!B15+Assumptions!B16)*Assumptions!B20 -> 0 | F19: =(Assumptions!B15+Assumptions!B16)*Assumptions!B20 -> 0 | G19: =(Assumptions!B15+Assumptions!B16)*Assumptions!B20 -> 0 | H19: =(Assumptions!B15+Assumptions!B16)*Assumptions!B20 -> 0 | I19: =SUM(B19:H19) -> 0
A20: Content creators 3× students (monthly) | B20: - | C20: =Assumptions!$B$17*Assumptions!$B$5 -> 213 | D20: =Assumptions!$B$17*Assumptions!$B$5 -> 213 | E20: =Assumptions!$B$17*Assumptions!$B$5 -> 213 | F20: =Assumptions!$B$17*Assumptions!$B$5 -> 213 | G20: =Assumptions!$B$17*Assumptions!$B$5 -> 213 | H20: =Assumptions!$B$17*Assumptions!$B$5 -> 213 | I20: =SUM(B20:H20) -> 1278
A21: Benefits allowance | B21: - | C21: =Assumptions!$B$43 -> 200 | D21: =Assumptions!$B$43 -> 200 | E21: =Assumptions!$B$43 -> 200 | F21: =Assumptions!$B$43 -> 200 | G21: =Assumptions!$B$43 -> 200 | H21: =Assumptions!$B$43 -> 200 | I21: =SUM(B21:H21) -> 1200
A22: Team outing (quarterly: Jun, Sep, Dec) | B22: - | C22: 0 | D22: 0 | E22: 500 | F22: 0 | G22: 0 | H22: 500 | I22: =SUM(B22:H22) -> 1000
A23: TOTAL PEOPLE COSTS | B23: =SUM(B12:B22) -> 0 | C23: =SUM(C12:C22) -> 31393 | D23: =SUM(D12:D22) -> 31393 | E23: =SUM(E12:E22) -> 31893 | F23: =SUM(F12:F22) -> 31393 | G23: =SUM(G12:G22) -> 31393 | H23: =SUM(H12:H22) -> 31893 | I23: =SUM(B23:H23) -> 189358
A25: COSTS — EVENTS
A26: Food & drinks | B26: =Assumptions!B23*2 -> 1000 | C26: =Assumptions!$B$23*2 -> 1000 | D26: =Assumptions!$B$23*2 -> 1000 | E26: =Assumptions!$B$23*Assumptions!$B$22 -> 1500 | F26: =Assumptions!$B$23*Assumptions!$B$22 -> 1500 | G26: =Assumptions!$B$23*5 -> 2500 | H26: =Assumptions!$B$23*5 -> 2500 | I26: =SUM(B26:H26) -> 11000
A27: Event promotion | B27: =Assumptions!B24*2 -> 400 | C27: =Assumptions!$B$24*2 -> 400 | D27: =Assumptions!$B$24*2 -> 400 | E27: =Assumptions!$B$24*Assumptions!$B$22 -> 600 | F27: =Assumptions!$B$24*Assumptions!$B$22 -> 600 | G27: =Assumptions!$B$24*5 -> 1000 | H27: =Assumptions!$B$24*5 -> 1000 | I27: =SUM(B27:H27) -> 4400
A28: Venue / location | B28: =Assumptions!B23*Assumptions!B20 -> 0 | C28: =Assumptions!B23*Assumptions!B20 -> 0 | D28: =Assumptions!B23*Assumptions!B20 -> 0 | E28: =Assumptions!B23*Assumptions!B20 -> 0 | F28: =Assumptions!B23*Assumptions!B20 -> 0 | G28: =Assumptions!B23*Assumptions!B20 -> 0 | H28: =Assumptions!B23*Assumptions!B20 -> 0 | I28: =SUM(B28:H28) -> 0
A29: TOTAL EVENT COSTS | B29: =SUM(B26:B28) -> 1400 | C29: =SUM(C26:C28) -> 1400 | D29: =SUM(D26:D28) -> 1400 | E29: =SUM(E26:E28) -> 2100 | F29: =SUM(F26:F28) -> 2100 | G29: =SUM(G26:G28) -> 3500 | H29: =SUM(H26:H28) -> 3500 | I29: =SUM(B29:H29) -> 15400
A31: COSTS — MARKETING & OPERATIONS
A32: Marketing budget | B32: =Assumptions!$B$28 -> 5000 | C32: =Assumptions!$B$28 -> 5000 | D32: =Assumptions!$B$28 -> 5000 | E32: =Assumptions!$B$28 -> 5000 | F32: =Assumptions!$B$28 -> 5000 | G32: =Assumptions!$B$28 -> 5000 | H32: =Assumptions!$B$28 -> 5000 | I32: =SUM(B32:H32) -> 35000
A33: Office / coworking | B33: =Assumptions!$B$29 -> 1000 | C33: =Assumptions!$B$29 -> 1000 | D33: =Assumptions!$B$29 -> 1000 | E33: =Assumptions!$B$29 -> 1000 | F33: =Assumptions!$B$29 -> 1000 | G33: =Assumptions!$B$29 -> 1000 | H33: =Assumptions!$B$29 -> 1000 | I33: =SUM(B33:H33) -> 7000
A34: Software (headcount × €100) | B34: =Assumptions!$B$31*Assumptions!$B$30 -> 1000 | C34: =Assumptions!$B$31*Assumptions!$B$30 -> 1000 | D34: =Assumptions!$B$31*Assumptions!$B$30 -> 1000 | E34: =Assumptions!$B$31*Assumptions!$B$30 -> 1000 | F34: =Assumptions!$B$31*Assumptions!$B$30 -> 1000 | G34: =Assumptions!$B$31*Assumptions!$B$30 -> 1000 | H34: =Assumptions!$B$31*Assumptions!$B$30 -> 1000 | I34: =SUM(B34:H34) -> 7000
A35: App hosting & infra | B35: =Assumptions!B29 -> 1000 | C35: =Assumptions!B29 -> 1000 | D35: =Assumptions!B29 -> 1000 | E35: =Assumptions!B29 -> 1000 | F35: =Assumptions!B29 -> 1000 | G35: =Assumptions!B29 -> 1000 | H35: =Assumptions!B29 -> 1000 | I35: =SUM(B35:H35) -> 7000
A36: Domestic travel NL | B36: =Assumptions!$B$33 -> 400 | C36: =Assumptions!$B$33 -> 400 | D36: =Assumptions!$B$33 -> 400 | E36: =Assumptions!$B$33 -> 400 | F36: =Assumptions!$B$33 -> 400 | G36: =Assumptions!$B$33 -> 400 | H36: =Assumptions!$B$33 -> 400 | I36: =SUM(B36:H36) -> 2800
A37: TOTAL MARKETING & OPS | B37: =SUM(B32:B36) -> 8400 | C37: =SUM(C32:C36) -> 8400 | D37: =SUM(D32:D36) -> 8400 | E37: =SUM(E32:E36) -> 8400 | F37: =SUM(F32:F36) -> 8400 | G37: =SUM(G32:G36) -> 8400 | H37: =SUM(H32:H36) -> 8400 | I37: =SUM(B37:H37) -> 58800
A39: COSTS — LEGAL, FINANCE & ADMIN
A40: Legal — incorporation + agreements (one-off) | B40: =Assumptions!B36 -> 3500 | C40: 0 | D40: 0 | E40: 0 | F40: 0 | G40: 0 | H40: 0 | I40: =SUM(B40:H40) -> 3500
A41: Legal — ongoing monthly | B41: =Assumptions!$B$37 -> 200 | C41: =Assumptions!$B$37 -> 200 | D41: =Assumptions!$B$37 -> 200 | E41: =Assumptions!$B$37 -> 200 | F41: =Assumptions!$B$37 -> 200 | G41: =Assumptions!$B$37 -> 200 | H41: =Assumptions!$B$37 -> 200 | I41: =SUM(B41:H41) -> 1400
A42: Accountancy / bookkeeping | B42: =Assumptions!$B$38 -> 500 | C42: =Assumptions!$B$38 -> 500 | D42: =Assumptions!$B$38 -> 500 | E42: =Assumptions!$B$38 -> 500 | F42: =Assumptions!$B$38 -> 500 | G42: =Assumptions!$B$38 -> 500 | H42: =Assumptions!$B$38 -> 500 | I42: =SUM(B42:H42) -> 3500
A43: Insurance | B43: =Assumptions!$B$39 -> 300 | C43: =Assumptions!$B$39 -> 300 | D43: =Assumptions!$B$39 -> 300 | E43: =Assumptions!$B$39 -> 300 | F43: =Assumptions!$B$39 -> 300 | G43: =Assumptions!$B$39 -> 300 | H43: =Assumptions!$B$39 -> 300 | I43: =SUM(B43:H43) -> 2100
A44: TOTAL LEGAL & FINANCE | B44: =SUM(B40:B43) -> 4500 | C44: =SUM(C40:C43) -> 1000 | D44: =SUM(D40:D43) -> 1000 | E44: =SUM(E40:E43) -> 1000 | F44: =SUM(F40:F43) -> 1000 | G44: =SUM(G40:G43) -> 1000 | H44: =SUM(H40:H43) -> 1000 | I44: =SUM(B44:H44) -> 10500
A46: SUMMARY
A47: TOTAL COSTS (before contingency) | B47: =B23+B29+B37+B44 -> 14300 | C47: =C23+C29+C37+C44 -> 42193 | D47: =D23+D29+D37+D44 -> 42193 | E47: =E23+E29+E37+E44 -> 43393 | F47: =F23+F29+F37+F44 -> 42893 | G47: =G23+G29+G37+G44 -> 44293 | H47: =H23+H29+H37+H44 -> 44793 | I47: =SUM(B47:H47) -> 274058
...

Sheet Bridge Summary
A1: BUZBO — Bridge Investment Summary | Jun–Dec 2026
A3: BRIDGE PERIOD TOTALS (Jun–Dec 2026)
A4: Total Revenue (7 months) | B4: ='Monthly P&L'!I9 -> 95717 | C4: Cross-referenced from P&L
A5: Total Costs (before contingency) | B5: ='Monthly P&L'!I47 -> 274058
A6: Contingency (12%) | B6: ='Monthly P&L'!I48 -> 0
A7: Total Costs (incl. contingency) | B7: ='Monthly P&L'!I49 -> 274058
A8: Net Burn (Revenue – Total Costs) | B8: ='Monthly P&L'!I51 -> -178341 | C8: Negative = cash needed
A10: RECOMMENDED BRIDGE RAISE
A11: Minimum required (absolute burn) | B11: =ABS('Monthly P&L'!I51) -> 178341 | C11: Cash needed to survive the bridge period
A12: Safety buffer (+25%) | B12: =ABS('Monthly P&L'!I51)*0.25 -> 44585.25 | C12: Standard buffer for delays, overruns, slower revenue ramp
A13: RECOMMENDED BRIDGE RAISE | B13: =ABS('Monthly P&L'!I51)*1.25 -> 222926.25 | C13: Round UP to nearest €25k for investor presentation
A15: USE OF FUNDS BREAKDOWN (approximate)
A16: People & salaries (incl. employer costs) | B16: ≈ 60% | C16: Largest line — 8 roles incl. 1 vacancy
A17: Marketing & growth | B17: ≈ 14% | C17: Paid channels, campaigns, tools
A18: Events (3/month × 3 cities) | B18: ≈ 8% | C18: Food, promo, hosts — venue currently €0
A19: Tech / hosting / software | B19: ≈ 4% | C19: App infra + team software
A20: Legal & finance | B20: ≈ 5% | C20: Incorporation, ongoing, accountancy, insurance
A21: Contingency & buffer (12% + 25%) | B21: ≈ 9% | C21: Pre-revenue standard
A23: INVESTOR NOTES
A24: • All salaries are net amounts; employer cost = net × 1.42 (NL social charges)
A25: • CEO salary starts June; all other salaries start July when bridge funding lands
A26: • Revenue is conservative: €10 ticket × 40 attendees, small membership cohort, 1 B2B client
A27: • Events: 3/month across Den Haag, Amsterdam, Rotterdam — scaling to more cities Q4
A28: • App goes live September 2026 → revenue ramp expected Q4 2026 onwards
A29: • Marketing Content Creator role is open vacancy — included in budget from July
A30: • Designer is freelance (invoice), no employer costs
A31: • Bridge raise bridges to Oct/Nov Series A — target €400k–800k institutional round
A32: • Equity: 60% Anouk / 20% Shinead / 20% option pool (CTO 5%, balance for future hires)

Sheet Headcount & Roles
A1: BUZBO — Headcount, Roles & Equity Overview
A3: # | B3: Name | C3: Role | D3: Type | E3: Net/mo | F3: Emp.Cost/mo | G3: Equity | H3: Notes
A4: 1 | B4: Anouk Horrevorts | C4: Founder & CEO | D4: Full-time | E4: €3,000 | F4: €4,260 | G4: 60% | H4: Founder. Starts Jun. 4yr vest 1yr cliff.
A5: 2 | B5: Shinead Pond | C5: Co-Founder & CCO | D5: Full-time | E5: €3,000 | F5: €4,260 | G5: 20% | H5: New agreement needed (upgrade from 10%). Starts Jul.
A6: 3 | B6: Tommy | C6: CTO | D6: Full-time | E6: €3,000 | F6: €4,260 | G6: 5% (option pool) | H6: 4yr vest 1yr cliff. Starts Jul.
A7: 4 | B7: Melanie | C7: Marketing | D7: PT 3d/wk | E7: €2,100 | F7: €2,982 | G7: — | H7: Starts Jul.
A8: 5 | B8: Mela | C8: Marketing | D8: PT 3d/wk | E8: €2,100 | F8: €2,982 | G8: — | H8: Starts Jul.
A9: 6 | B9: OPEN — Content Creator | C9: Social Media / Content | D9: Full-time | E9: €3,500 | F9: €4,970 | G9: — | H9: VACANCY — priority hire Jul. Included in budget.
A10: 7 | B10: Michael / Rhys | C10: Experience Designer | D10: Freelancer | E10: — | F10: €4,000 inv. | G10: — | H10: Invoice only, no employer cost. Starts Jul.
A11: 8 | B11: Chinar | C11: UX/UI + Events Ops | D11: PT (junior) | E11: €1,100 | F11: €1,562 | G11: — | H11: Min wage compliant. Events autonomy target. Starts Jul.
B12: Event Host — DH | C12: Event Host | D12: Per event | E12: — | F12: €300/event | G12: — | H12: Freelance per event
B13: Event Host — AMS | C13: Event Host | D13: Per event | E13: — | F13: €300/event | G13: —
B14: Event Host — RTD | C14: Event Host | D14: Per event | E14: — | F14: €300/event | G14: —
B15: Event Crew | C15: Support | D15: Per event | E15: — | F15: €150/event | G15: — | H15: 2× €75
A16: 9 | B16: Stella | C16: Content Creator 1 | D16: Monthly | E16: — | F16: €500/mo | G16: —
A17: 10 | B17: Maria | C17: Content Creator 1 | D17: Monthly | E17: — | F17: €500/mo | G17: —
A18: 11 | B18: Manuela | C18: Content Creator 1 | D18: Monthly | E18: — | F18: €500/mo | G18: —
A20: Option pool: 20% total | CTO: 5% | Remaining 15% for designer (future), senior hires, advisors, Shinead upside | All equity: 4yr vest, 1yr cliff
